Workbook

Sheet Colour Info
B2: Default Plant Colour | I2: Colour | J2: Mixing Palette | K2: 🡳 Mixed with White 🡳 | L2: Default Plant Colour
I3: White | J3: Cannot Be Made | K3: Cannot Mix
I4: Red | J4: Cannot Be Made | K4: Warm Pink
I5: Coral | J5: 🡲 Red + Orange | K5: Blush
I6: Orange | J6: 🡲 Red + Yellow | K6: Peach
I7: Yellow | J7: Cannot Be Made | K7: Cream
I8: Lime | J8: 🡲 Green + Yellow | K8: Pistachio
I9: Green | J9: 🡲 Yellow + Blue | K9: Mint
I10: Teal | J10: 🡲 Green + Sky | K10: Seafoam
I11: Sky | J11: Cannot Be Made | K11: Cloud
I12: Blue | J12: Cannot Be Made | K12: Ice
I13: Indigo | J13: 🡲 Blue + Violet | K13: Periwinkle
I14: Violet | J14: 🡲 Blue + Red | K14: Lilac
... I16: Hot Pink | J16: Cannot Be Made | K16: Pink
H18: 🡰 indicates event flower | K18: indicates dlc flower 🡲
H19: 🡰 indicates extremophile flower

Sheet CHECK ALL BOXES 
A1: How to use: Click on each flower below + pattern to check all the boxes in a column.
A3: For example:
A4: Clicking on the rose will check all solid rose colours in the default colours page
A5: Clicking on the stripe pattern will check all stripe colours in the default colours page
A7: FEEL FREE TO DELETE THIS PAGE WHEN YOU ARE FINISHED
K9: Click on Advanced and click on the link at the bottom 🢂
I10: "Go to HKIA Flower Tracker By Selene"
I12: Follow the steps and continue through.

Sheet Default Colours
A1: Flower
B2: Anemone | D2: Bellbutton | F2: Dandelily | H2: Dreampuff | J2: Ghostgleam | L2: Heavy Nettle | N2: Hibiscus | P2: Penstemum | R2: Thistle | T2: Tulias | V2: Blazebulb | X2: Crystalia | Z2: Frostfeather | AB2: Bowblossom | AD2: Eggwort | AF2: Glowbal | AH2: Happadil | AJ2: Happadil | AL2: Marigold | AP2: Petunia | AR2: Pinwheel | AV2: Poinsettia | AX2: Rose | AZ2: Wheat flower
A3: Biome | X3: Caves | AD3: ALL
A4: Pattern → Colour ↓
B5: Solid | C5: Ombre | D5: Solid | E5: Ombre | F5: Solid | G5: Ombre | H5: Solid | I5: Ombre | J5: Solid | K5: Ombre | L5: Solid | M5: Ombre | N5: Solid | O5: Ombre | P5: Solid | Q5: Ombre | R5: Solid | S5: Ombre | T5: Solid | U5: Ombre | V5: Solid | W5: Molten | X5: Solid | Y5: Crystal | Z5: Solid | AA5: Frost | AB5: Solid | AC5: Iridescent | AD5: Solid | AE5: Speckled | AF5: Solid | AG5: Glow | AH5: Solid | AI5: Con fetti | AJ5: Solid | AK5: Confetti | AL5: Solid | AN5: Trim | AP5: Solid | AQ5: Striped | AR5: Solid | AT5: Alternate | AV5: Solid | AW5: Patch | AX5: Solid | AY5: Ring | AZ5: Solid | BA5: Glitter
A6: Black | B6: FALSE | C6: FALSE | D6: TRUE | E6: FALSE | F6: FALSE | G6: FALSE | H6: FALSE | I6: FALSE | J6: FALSE | K6: FALSE | L6: FALSE | M6: FALSE | N6: FALSE | O6: FALSE | P6: FALSE | Q6: FALSE | R6: FALSE | S6: FALSE | T6: TRUE | U6: TRUE | V6: FALSE | W6: FALSE | X6: FALSE | Y6: FALSE | Z6: FALSE | AA6: FALSE | AB6: TRUE | AC6: TRUE | AD6: FALSE | AE6: FALSE | AF6: TRUE | AG6: FALSE | AH6: FALSE | AI6: FALSE | AJ6: FALSE | AK6: FALSE | AL6: FALSE | AN6: FALSE | AP6: FALSE | AQ6: FALSE | AR6: FALSE | AT6: FALSE | AV6: FALSE | AW6: FALSE | AX6: FALSE | AY6: FALSE | AZ6: FALSE | BA6: FALSE
A7: Grey | B7: FALSE | C7: FALSE | D7: TRUE | E7: FALSE | F7: FALSE | G7: FALSE | H7: FALSE | I7: FALSE | J7: FALSE | K7: FALSE | L7: FALSE | M7: FALSE | N7: FALSE | O7: FALSE | P7: FALSE | Q7: FALSE | R7: FALSE | S7: FALSE | T7: TRUE | U7: TRUE | V7: FALSE | W7: FALSE | X7: FALSE | Y7: FALSE | Z7: FALSE | AA7: FALSE | AB7: TRUE | AC7: FALSE | AD7: FALSE | AE7: FALSE | AF7: FALSE | AG7: FALSE | AH7: FALSE | AI7: FALSE | AJ7: FALSE | AK7: FALSE | AL7: FALSE | AN7: FALSE | AP7: FALSE | AQ7: FALSE | AR7: FALSE | AT7: FALSE | AV7: FALSE | AW7: FALSE | AX7: FALSE | AY7: FALSE | AZ7: FALSE | BA7: FALSE
A8: White | B8: TRUE | C8: FALSE | D8: TRUE | E8: FALSE | F8: TRUE | G8: TRUE | H8: TRUE | I8: FALSE | J8: TRUE | K8: TRUE | L8: TRUE | M8: TRUE | N8: TRUE | O8: TRUE | P8: TRUE | Q8: TRUE | R8: TRUE | S8: TRUE | T8: TRUE | U8: TRUE | V8: FALSE | W8: FALSE | X8: FALSE | Y8: FALSE | Z8: FALSE | AA8: FALSE | AB8: TRUE | AC8: TRUE | AD8: FALSE | AE8: FALSE | AF8: TRUE | AG8: TRUE | AH8: FALSE | AI8: FALSE | AJ8: FALSE | AK8: FALSE | AL8: TRUE | AN8: FALSE | AP8: TRUE | AQ8: TRUE | AR8: TRUE | AT8: FALSE | AV8: TRUE | AW8: FALSE | AX8: TRUE | AY8: FALSE | AZ8: TRUE | BA8: TRUE
A9: Red | B9: FALSE | C9: FALSE | D9: TRUE | E9: TRUE | F9: TRUE | G9: TRUE | H9: TRUE | I9: TRUE | J9: TRUE | K9: TRUE | L9: TRUE | M9: FALSE | N9: TRUE | O9: TRUE | P9: TRUE | Q9: TRUE | R9: TRUE | S9: FALSE | T9: TRUE | U9: TRUE | V9: FALSE | W9: FALSE | X9: FALSE | Y9: FALSE | Z9: FALSE | AA9: FALSE | AB9: TRUE | AC9: FALSE | AD9: FALSE | AE9: FALSE | AF9: TRUE | AG9: TRUE | AH9: FALSE | AI9: FALSE | AJ9: FALSE | AK9: FALSE | AL9: TRUE | AN9: TRUE | AP9: TRUE | AQ9: FALSE | AR9: TRUE | AT9: TRUE | AV9: TRUE | AW9: FALSE | AX9: TRUE | AY9: FALSE | AZ9: TRUE | BA9: TRUE
A10: Warm Pink | B10: FALSE | C10: FALSE | D10: TRUE | E10: TRUE | F10: TRUE | G10: TRUE | H10: TRUE | I10: FALSE | J10: TRUE | K10: TRUE | L10: TRUE | M10: FALSE | N10: TRUE | O10: TRUE | P10: TRUE | Q10: TRUE | R10: TRUE | S10: FALSE | T10: TRUE | U10: TRUE | V10: FALSE | W10: FALSE | X10: FALSE | Y10: FALSE | Z10: FALSE | AA10: FALSE | AB10: TRUE | AC10: FALSE | AD10: FALSE | AE10: FALSE | AF10: TRUE | AG10: FALSE | AH10: FALSE | AI10: FALSE | AJ10: FALSE | AK10: FALSE | AL10: TRUE | AN10: TRUE | AP10: FALSE | AQ10: FALSE | AR10: TRUE | AT10: TRUE | AV10: FALSE | AW10: FALSE | AX10: FALSE | AY10: FALSE | AZ10: TRUE | BA10: FALSE
A11: Coral | B11: TRUE | C11: TRUE | D11: TRUE | E11: TRUE | F11: TRUE | G11: TRUE | H11: TRUE | I11: FALSE | J11: TRUE | K11: TRUE | L11: TRUE | M11: TRUE | N11: TRUE | O11: TRUE | P11: TRUE | Q11: TRUE | R11: TRUE | S11: FALSE | T11: TRUE | U11: TRUE | V11: FALSE | W11: FALSE | X11: FALSE | Y11: FALSE | Z11: FALSE | AA11: FALSE | AB11: TRUE | AC11: FALSE | AD11: FALSE | AE11: FALSE | AF11: TRUE | AG11: FALSE | AH11: FALSE | AI11: FALSE | AJ11: FALSE | AK11: FALSE | AL11: TRUE | AN11: FALSE | AP11: TRUE | AQ11: FALSE | AR11: TRUE | AT11: TRUE | AV11: FALSE | AW11: FALSE | AX11: FALSE | AY11: FALSE | AZ11: TRUE | BA11: FALSE
A12: Blush | B12: TRUE | C12: FALSE | D12: TRUE | E12: TRUE | F12: TRUE | G12: TRUE | H12: FALSE | I12: FALSE | J12: TRUE | K12: TRUE | L12: TRUE | M12: TRUE | N12: TRUE | O12: FALSE | P12: TRUE | Q12: TRUE | R12: TRUE | S12: FALSE | T12: TRUE | U12: FALSE | V12: TRUE | W12: TRUE | X12: FALSE | Y12: TRUE | Z12: FALSE | AA12: FALSE | AB12: TRUE | AC12: FALSE | AD12: FALSE | AE12: FALSE | AF12: TRUE | AG12: FALSE | AH12: FALSE | AI12: FALSE | AJ12: FALSE | AK12: FALSE | AL12: TRUE | AN12: FALSE | AP12: FALSE | AQ12: FALSE | AR12: TRUE | AT12: FALSE | AV12: FALSE | AW12: FALSE | AX12: FALSE | AY12: FALSE | AZ12: TRUE | BA12: FALSE
A13: Orange | B13: FALSE | C13: FALSE | D13: TRUE | E13: TRUE | F13: TRUE | G13: TRUE | H13: TRUE | I13: TRUE | J13: TRUE | K13: FALSE | L13: TRUE | M13: TRUE | N13: TRUE | O13: TRUE | P13: TRUE | Q13: TRUE | R13: TRUE | S13: TRUE | T13: TRUE | U13: TRUE | V13: FALSE | W13: FALSE | X13: FALSE | Y13: FALSE | Z13: FALSE | AA13: FALSE | AB13: TRUE | AC13: FALSE | AD13: FALSE | AE13: FALSE | AF13: TRUE | AG13: FALSE | AH13: FALSE | AI13: FALSE | AJ13: FALSE | AK13: FALSE | AL13: TRUE | AN13: TRUE | AP13: TRUE | AQ13: FALSE | AR13: TRUE | AT13: TRUE | AV13: FALSE | AW13: FALSE | AX13: FALSE | AY13: FALSE | AZ13: TRUE | BA13: TRUE
A14: Peach | B14: FALSE | C14: FALSE | D14: TRUE | E14: FALSE | F14: TRUE | G14: TRUE | H14: TRUE | I14: FALSE | J14: TRUE | K14: FALSE | L14: TRUE | M14: FALSE | N14: TRUE | O14: FALSE | P14: TRUE | Q14: TRUE | R14: TRUE | S14: FALSE | T14: TRUE | U14: FALSE | V14: TRUE | W14: FALSE | X14: FALSE | Y14: FALSE | Z14: FALSE | AA14: FALSE | AB14: TRUE | AC14: FALSE | AD14: FALSE | AE14: FALSE | AF14: TRUE | AG14: FALSE | AH14: FALSE | AI14: FALSE | AJ14: FALSE | AK14: FALSE | AL14: TRUE | AN14: TRUE | AP14: FALSE | AQ14: FALSE | AR14: TRUE | AT14: FALSE | AV14: FALSE | AW14: FALSE | AX14: FALSE | AY14: FALSE | AZ14: TRUE | BA14: TRUE
A15: Yellow | B15: TRUE | C15: FALSE | D15: TRUE | E15: TRUE | F15: TRUE | G15: TRUE | H15: TRUE | I15: TRUE | J15: TRUE | K15: TRUE | L15: TRUE | M15: FALSE | N15: TRUE | O15: TRUE | P15: TRUE | Q15: TRUE | R15: TRUE | S15: TRUE | T15: TRUE | U15: FALSE | V15: FALSE | W15: FALSE | X15: FALSE | Y15: FALSE | Z15: FALSE | AA15: FALSE | AB15: TRUE | AC15: FALSE | AD15: FALSE | AE15: FALSE | AF15: TRUE | AG15: FALSE | AH15: FALSE | AI15: FALSE | AJ15: FALSE | AK15: FALSE | AL15: TRUE | AN15: FALSE | AP15: TRUE | AQ15: FALSE | AR15: TRUE | AT15: TRUE | AV15: FALSE | AW15: FALSE | AX15: TRUE | AY15: FALSE | AZ15: TRUE | BA15: FALSE
A16: Cream | B16: FALSE | C16: FALSE | D16: TRUE | E16: FALSE | F16: TRUE | G16: TRUE | H16: TRUE | I16: FALSE | J16: TRUE | K16: FALSE | L16: FALSE | M16: FALSE | N16: TRUE | O16: FALSE | P16: TRUE | Q16: FALSE | R16: TRUE | S16: FALSE | T16: TRUE | U16: TRUE | V16: TRUE | W16: TRUE | X16: FALSE | Y16: FALSE | Z16: FALSE | AA16: FALSE | AB16: TRUE | AC16: FALSE | AD16: FALSE | AE16: FALSE | AF16: TRUE | AG16: FALSE | AH16: FALSE | AI16: FALSE | AJ16: FALSE | AK16: FALSE | AL16: TRUE | AN16: FALSE | AP16: FALSE | AQ16: FALSE | AR16: TRUE | AT16: FALSE | AV16: FALSE | AW16: FALSE | AX16: FALSE | AY16: FALSE | AZ16: TRUE | BA16: TRUE
A17: Lime | B17: TRUE | C17: TRUE | D17: TRUE | E17: TRUE | F17: TRUE | G17: TRUE | H17: FALSE | I17: FALSE | J17: TRUE | K17: FALSE | L17: FALSE | M17: FALSE | N17: TRUE | O17: TRUE | P17: TRUE | Q17: TRUE | R17: TRUE | S17: TRUE | T17: TRUE | U17: FALSE | V17: FALSE | W17: FALSE | X17: FALSE | Y17: FALSE | Z17: FALSE | AA17: FALSE | AB17: TRUE | AC17: FALSE | AD17: FALSE | AE17: FALSE | AF17: TRUE | AG17: FALSE | AH17: FALSE | AI17: FALSE | AJ17: FALSE | AK17: FALSE | AL17: TRUE | AN17: FALSE | AP17: TRUE | AQ17: FALSE | AR17: TRUE | AT17: TRUE | AV17: FALSE | AW17: FALSE | AX17: FALSE | AY17: FALSE | AZ17: TRUE | BA17: FALSE
... A34: Pink | B34: FALSE | C34: FALSE | D34: TRUE | E34: TRUE | F34: TRUE | G34: TRUE | H34: FALSE | I34: FALSE | J34: TRUE | K34: FALSE | L34: TRUE | M34: TRUE | N34: TRUE | O34: FALSE | P34: TRUE | Q34: FALSE | R34: TRUE | S34: FALSE | T34: TRUE | U34: TRUE | V34: FALSE | W34: FALSE | X34: TRUE | Y34: FALSE | Z34: FALSE | AA34: FALSE | AB34: FALSE | AC34: FALSE | AD34: FALSE | AE34: FALSE | AF34: TRUE | AG34: FALSE | AH34: FALSE | AI34: FALSE | AJ34: FALSE | AK34: FALSE | AL34: FALSE | AN34: FALSE | AP34: FALSE | AQ34: FALSE | AR34: TRUE | AT34: TRUE | AV34: FALSE | AW34: FALSE | AX34: TRUE | AY34: TRUE | AZ34: TRUE | BA34: FALSE
A35: Have: | B35: =COUNTIF(B6:B34, TRUE) -> 14 | C35: =COUNTIF(C6:C34, TRUE) -> 4 | D35: =COUNTIF(D6:D34, TRUE) -> 29 | E35: =COUNTIF(E6:E34, TRUE) -> 17 | F35: =COUNTIF(F6:F34, TRUE) -> 27 | G35: =COUNTIF(G6:G34, TRUE) -> 24 | H35: =COUNTIF(H6:H34, TRUE) -> 18 | I35: =COUNTIF(I6:I34, TRUE) -> 8 | ... AI35: =COUNTIF(AI6:AI34, TRUE) -> 0 | AJ35: =COUNTIF(AJ8:AJ34, TRUE) -> 0 | AK35: =COUNTIF(AK8:AK34, TRUE) -> 0 | AL35: =COUNTIF(AL6:AL34, TRUE) -> 21 | AN35: =COUNTIF(AN6:AN34, TRUE) -> 8 | AP35: =COUNTIF(AP6:AP34, TRUE) -> 11 | AQ35: =COUNTIF(AQ6:AQ34, TRUE) -> 3 | AR35: =COUNTIF(AR6:AR34, TRUE) -> 27 | AT35: =COUNTIF(AT6:AT34, TRUE) -> 15 | AV35: =COUNTIF(AV6:AV34, TRUE) -> 2 | AW35: =COUNTIF(AW6:AW34, TRUE) -> 0 | AX35: =COUNTIF(AX6:AX34, TRUE) -> 5 | AY35: =COUNTIF(AY6:AY34, TRUE) -> 1 | AZ35: =COUNTIF(AZ6:AZ34, TRUE) -> 24 | BA35: =COUNTIF(BA6:BA34, TRUE) -> 10
A36: Need: | B36: =COUNTIF(B6:B34, FALSE) -> 15 | C36: =COUNTIF(C6:C34, FALSE) -> 25 | D36: =COUNTIF(D6:D34, FALSE) -> 0 | E36: =COUNTIF(E6:E34, FALSE) -> 12 | F36: =COUNTIF(F6:F34, FALSE) -> 2 | G36: =COUNTIF(G6:G34, FALSE) -> 5 | H36: =COUNTIF(H6:H34, FALSE) -> 11 | I36: =COUNTIF(I6:I34, FALSE) -> 21 | ... AI36: =COUNTIF(AI6:AI34, FALSE) -> 29 | AJ36: =COUNTIF(AJ8:AJ34, FALSE) -> 27 | AK36: =COUNTIF(AK8:AK34, FALSE) -> 27 | AL36: =COUNTIF(AL6:AL34, FALSE) -> 8 | AN36: =COUNTIF(AN6:AN34, FALSE) -> 21 | AP36: =COUNTIF(AP6:AP34, FALSE) -> 18 | AQ36: =COUNTIF(AQ6:AQ34, FALSE) -> 26 | AR36: =COUNTIF(AR6:AR34, FALSE) -> 2 | AT36: =COUNTIF(AT6:AT34, FALSE) -> 14 | AV36: =COUNTIF(AV6:AV34, FALSE) -> 27 | AW36: =COUNTIF(AW6:AW34, FALSE) -> 29 | AX36: =COUNTIF(AX6:AX34, FALSE) -> 24 | AY36: =COUNTIF(AY6:AY34, FALSE) -> 28 | AZ36: =COUNTIF(AZ6:AZ34, FALSE) -> 5 | BA36: =COUNTIF(BA6:BA34, FALSE) -> 19

Sheet Ombre
A1: Flower
B2: Anemone | C2: Bellbutton | D2: Dandelily | E2: Dreampuff | F2: Ghostgleam | G2: Heavy Nettle | H2: Hibiscus | I2: Penste mum | J2: Thistle | K2: Tulias | L2: Blazebulb | M2: Crystalia | N2: Frost feather | O2: Bow blossom | P2: Eggwort | Q2: Glowbal | R2: Happadil | S2: Happadil | U2: Marigold | V2: Petunia | W2: Pinwheel | X2: Poinsettia | Y2: Rose | Z2: Wheat flower
A3: Pattern → Colour ↓
A4: Black | B4: =IF('Default Colours'!C6=TRUE,TRUE, FALSE) -> FALSE | C4: =IF('Default Colours'!E6=TRUE,TRUE, FALSE) -> FALSE | D4: =IF('Default Colours'!G6=TRUE,TRUE, FALSE) -> FALSE | E4: =IF('Default Colours'!I6=TRUE,TRUE, FALSE) -> FALSE | F4: =IF('Default Colours'!K6=TRUE,TRUE, FALSE) -> FALSE | G4: =IF('Default Colours'!M6=TRUE,TRUE, FALSE) -> FALSE | H4: =IF('Default Colours'!O6=TRUE,TRUE, FALSE) -> FALSE | I4: =IF('Default Colours'!Q6=TRUE,TRUE, FALSE) -> FALSE | J4: =IF('Default Colours'!S6=TRUE,TRUE, FALSE) -> FALSE | K4: =IF('Default Colours'!U6=TRUE,TRUE, FALSE) -> TRUE | L4: FALSE | M4: FALSE | N4: FALSE | O4: FALSE | P4: FALSE | Q4: FALSE | R4: FALSE | S4: FALSE | T4: FALSE | U4: FALSE | V4: FALSE | W4: FALSE | X4: FALSE | Y4: FALSE | Z4: FALSE
A5: Grey | B5: =IF('Default Colours'!C7=TRUE,TRUE, FALSE) -> FALSE | C5: =IF('Default Colours'!E7=TRUE,TRUE, FALSE) -> FALSE | D5: =IF('Default Colours'!G7=TRUE,TRUE, FALSE) -> FALSE | E5: =IF('Default Colours'!I7=TRUE,TRUE, FALSE) -> FALSE | F5: =IF('Default Colours'!K7=TRUE,TRUE, FALSE) -> FALSE | G5: =IF('Default Colours'!M7=TRUE,TRUE, FALSE) -> FALSE | H5: =IF('Default Colours'!O7=TRUE,TRUE, FALSE) -> FALSE | I5: =IF('Default Colours'!Q7=TRUE,TRUE, FALSE) -> FALSE | J5: =IF('Default Colours'!S7=TRUE,TRUE, FALSE) -> FALSE | K5: =IF('Default Colours'!U7=TRUE,TRUE, FALSE) -> TRUE | L5: FALSE | M5: FALSE | N5: FALSE | O5: FALSE | P5: FALSE | Q5: FALSE | R5: FALSE | S5: FALSE | T5: FALSE | U5: FALSE | V5: FALSE | W5: FALSE | X5: FALSE | Y5: FALSE | Z5: FALSE
A6: White | B6: =IF('Default Colours'!C8=TRUE,TRUE, FALSE) -> FALSE | C6: =IF('Default Colours'!E8=TRUE,TRUE, FALSE) -> FALSE | D6: =IF('Default Colours'!G8=TRUE,TRUE, FALSE) -> TRUE | E6: =IF('Default Colours'!I8=TRUE,TRUE, FALSE) -> FALSE | F6: =IF('Default Colours'!K8=TRUE,TRUE, FALSE) -> TRUE | G6: =IF('Default Colours'!M8=TRUE,TRUE, FALSE) -> TRUE | H6: =IF('Default Colours'!O8=TRUE,TRUE, FALSE) -> TRUE | I6: =IF('Default Colours'!Q8=TRUE,TRUE, FALSE) -> TRUE | J6: =IF('Default Colours'!S8=TRUE,TRUE, FALSE) -> TRUE | K6: =IF('Default Colours'!U8=TRUE,TRUE, FALSE) -> TRUE | L6: FALSE | M6: FALSE | N6: FALSE | O6: FALSE | P6: FALSE | Q6: FALSE | R6: FALSE | S6: FALSE | T6: FALSE | U6: FALSE | V6: FALSE | W6: FALSE | X6: FALSE | Y6: FALSE | Z6: FALSE
A7: Red | B7: =IF('Default Colours'!C9=TRUE,TRUE, FALSE) -> FALSE | C7: =IF('Default Colours'!E9=TRUE,TRUE, FALSE) -> TRUE | D7: =IF('Default Colours'!G9=TRUE,TRUE, FALSE) -> TRUE | E7: =IF('Default Colours'!I9=TRUE,TRUE, FALSE) -> TRUE | F7: =IF('Default Colours'!K9=TRUE,TRUE, FALSE) -> TRUE | G7: =IF('Default Colours'!M9=TRUE,TRUE, FALSE) -> FALSE | H7: =IF('Default Colours'!O9=TRUE,TRUE, FALSE) -> TRUE | I7: =IF('Default Colours'!Q9=TRUE,TRUE, FALSE) -> TRUE | J7: =IF('Default Colours'!S9=TRUE,TRUE, FALSE) -> FALSE | K7: =IF('Default Colours'!U9=TRUE,TRUE, FALSE) -> TRUE | L7: FALSE | M7: FALSE | N7: FALSE | O7: FALSE | P7: FALSE | Q7: FALSE | R7: FALSE | S7: FALSE | T7: FALSE | U7: FALSE | V7: FALSE | W7: FALSE | X7: FALSE | Y7: FALSE | Z7: FALSE
A8: Warm Pink | B8: =IF('Default Colours'!C10=TRUE,TRUE, FALSE) -> FALSE | C8: =IF('Default Colours'!E10=TRUE,TRUE, FALSE) -> TRUE | D8: =IF('Default Colours'!G10=TRUE,TRUE, FALSE) -> TRUE | E8: =IF('Default Colours'!I10=TRUE,TRUE, FALSE) -> FALSE | F8: =IF('Default Colours'!K10=TRUE,TRUE, FALSE) -> TRUE | G8: =IF('Default Colours'!M10=TRUE,TRUE, FALSE) -> FALSE | H8: =IF('Default Colours'!O10=TRUE,TRUE, FALSE) -> TRUE | I8: =IF('Default Colours'!Q10=TRUE,TRUE, FALSE) -> TRUE | J8: =IF('Default Colours'!S10=TRUE,TRUE, FALSE) -> FALSE | K8: =IF('Default Colours'!U10=TRUE,TRUE, FALSE) -> TRUE | L8: FALSE | M8: FALSE | N8: FALSE | O8: FALSE | P8: FALSE | Q8: FALSE | R8: FALSE | S8: FALSE | T8: FALSE | U8: FALSE | V8: FALSE | W8: FALSE | X8: FALSE | Y8: FALSE | Z8: FALSE
A9: Coral | B9: =IF('Default Colours'!C11=TRUE,TRUE, FALSE) -> TRUE | C9: =IF('Default Colours'!E11=TRUE,TRUE, FALSE) -> TRUE | D9: =IF('Default Colours'!G11=TRUE,TRUE, FALSE) -> TRUE | E9: =IF('Default Colours'!I11=TRUE,TRUE, FALSE) -> FALSE | F9: =IF('Default Colours'!K11=TRUE,TRUE, FALSE) -> TRUE | G9: =IF('Default Colours'!M11=TRUE,TRUE, FALSE) -> TRUE | H9: =IF('Default Colours'!O11=TRUE,TRUE, FALSE) -> TRUE | I9: =IF('Default Colours'!Q11=TRUE,TRUE, FALSE) -> TRUE | J9: =IF('Default Colours'!S11=TRUE,TRUE, FALSE) -> FALSE | K9: =IF('Default Colours'!U11=TRUE,TRUE, FALSE) -> TRUE | L9: FALSE | M9: FALSE | N9: FALSE | O9: FALSE | P9: FALSE | Q9: FALSE | R9: FALSE | S9: FALSE | T9: FALSE | U9: FALSE | V9: FALSE | W9: FALSE | X9: FALSE | Y9: FALSE | Z9: FALSE
A10: Blush | B10: =IF('Default Colours'!C12=TRUE,TRUE, FALSE) -> FALSE | C10: =IF('Default Colours'!E12=TRUE,TRUE, FALSE) -> TRUE | D10: =IF('Default Colours'!G12=TRUE,TRUE, FALSE) -> TRUE | E10: =IF('Default Colours'!I12=TRUE,TRUE, FALSE) -> FALSE | F10: =IF('Default Colours'!K12=TRUE,TRUE, FALSE) -> TRUE | G10: =IF('Default Colours'!M12=TRUE,TRUE, FALSE) -> TRUE | H10: =IF('Default Colours'!O12=TRUE,TRUE, FALSE) -> FALSE | I10: =IF('Default Colours'!Q12=TRUE,TRUE, FALSE) -> TRUE | J10: =IF('Default Colours'!S12=TRUE,TRUE, FALSE) -> FALSE | K10: =IF('Default Colours'!U12=TRUE,TRUE, FALSE) -> FALSE | L10: FALSE | M10: FALSE | N10: FALSE | O10: FALSE | P10: FALSE | Q10: FALSE | R10: FALSE | S10: FALSE | T10: FALSE | U10: FALSE | V10: FALSE | W10: FALSE | X10: FALSE | Y10: FALSE | Z10: FALSE
A11: Orange | B11: =IF('Default Colours'!C13=TRUE,TRUE, FALSE) -> FALSE | C11: =IF('Default Colours'!E13=TRUE,TRUE, FALSE) -> TRUE | D11: =IF('Default Colours'!G13=TRUE,TRUE, FALSE) -> TRUE | E11: =IF('Default Colours'!I13=TRUE,TRUE, FALSE) -> TRUE | F11: =IF('Default Colours'!K13=TRUE,TRUE, FALSE) -> FALSE | G11: =IF('Default Colours'!M13=TRUE,TRUE, FALSE) -> TRUE | H11: =IF('Default Colours'!O13=TRUE,TRUE, FALSE) -> TRUE | I11: =IF('Default Colours'!Q13=TRUE,TRUE, FALSE) -> TRUE | J11: =IF('Default Colours'!S13=TRUE,TRUE, FALSE) -> TRUE | K11: =IF('Default Colours'!U13=TRUE,TRUE, FALSE) -> TRUE | L11: FALSE | M11: FALSE | N11: FALSE | O11: FALSE | P11: FALSE | Q11: FALSE | R11: FALSE | S11: FALSE | T11: FALSE | U11: FALSE | V11: FALSE | W11: FALSE | X11: FALSE | Y11: FALSE | Z11: FALSE
A12: Peach | B12: =IF('Default Colours'!C14=TRUE,TRUE, FALSE) -> FALSE | C12: =IF('Default Colours'!E14=TRUE,TRUE, FALSE) -> FALSE | D12: =IF('Default Colours'!G14=TRUE,TRUE, FALSE) -> TRUE | E12: =IF('Default Colours'!I14=TRUE,TRUE, FALSE) -> FALSE | F12: =IF('Default Colours'!K14=TRUE,TRUE, FALSE) -> FALSE | G12: =IF('Default Colours'!M14=TRUE,TRUE, FALSE) -> FALSE | H12: =IF('Default Colours'!O14=TRUE,TRUE, FALSE) -> FALSE | I12: =IF('Default Colours'!Q14=TRUE,TRUE, FALSE) -> TRUE | J12: =IF('Default Colours'!S14=TRUE,TRUE, FALSE) -> FALSE | K12: =IF('Default Colours'!U14=TRUE,TRUE, FALSE) -> FALSE | L12: FALSE | M12: FALSE | N12: FALSE | O12: FALSE | P12: FALSE | Q12: FALSE | R12: FALSE | S12: FALSE | T12: FALSE | U12: FALSE | V12: FALSE | W12: FALSE | X12: FALSE | Y12: FALSE | Z12: FALSE
A13: Yellow | B13: =IF('Default Colours'!C15=TRUE,TRUE, FALSE) -> FALSE | C13: =IF('Default Colours'!E15=TRUE,TRUE, FALSE) -> TRUE | D13: =IF('Default Colours'!G15=TRUE,TRUE, FALSE) -> TRUE | E13: =IF('Default Colours'!I15=TRUE,TRUE, FALSE) -> TRUE | F13: =IF('Default Colours'!K15=TRUE,TRUE, FALSE) -> TRUE | G13: =IF('Default Colours'!M15=TRUE,TRUE, FALSE) -> FALSE | H13: =IF('Default Colours'!O15=TRUE,TRUE, FALSE) -> TRUE | I13: =IF('Default Colours'!Q15=TRUE,TRUE, FALSE) -> TRUE | J13: =IF('Default Colours'!S15=TRUE,TRUE, FALSE) -> TRUE | K13: =IF('Default Colours'!U15=TRUE,TRUE, FALSE) -> FALSE | L13: FALSE | M13: FALSE | N13: FALSE | O13: FALSE | P13: FALSE | Q13: FALSE | R13: FALSE | S13: FALSE | T13: FALSE | U13: FALSE | V13: FALSE | W13: FALSE | X13: FALSE | Y13: FALSE | Z13: TRUE
A14: Cream | B14: =IF('Default Colours'!C16=TRUE,TRUE, FALSE) -> FALSE | C14: =IF('Default Colours'!E16=TRUE,TRUE, FALSE) -> FALSE | D14: =IF('Default Colours'!G16=TRUE,TRUE, FALSE) -> TRUE | E14: =IF('Default Colours'!I16=TRUE,TRUE, FALSE) -> FALSE | F14: =IF('Default Colours'!K16=TRUE,TRUE, FALSE) -> FALSE | G14: =IF('Default Colours'!M16=TRUE,TRUE, FALSE) -> FALSE | H14: =IF('Default Colours'!O16=TRUE,TRUE, FALSE) -> FALSE | I14: =IF('Default Colours'!Q16=TRUE,TRUE, FALSE) -> FALSE | J14: =IF('Default Colours'!S16=TRUE,TRUE, FALSE) -> FALSE | K14: =IF('Default Colours'!U16=TRUE,TRUE, FALSE) -> TRUE | L14: FALSE | M14: FALSE | N14: FALSE | O14: FALSE | P14: FALSE | Q14: FALSE | R14: FALSE | S14: FALSE | T14: FALSE | U14: FALSE | V14: FALSE | W14: FALSE | X14: FALSE | Y14: FALSE | Z14: FALSE
A15: Lime | B15: =IF('Default Colours'!C17=TRUE,TRUE, FALSE) -> TRUE | C15: =IF('Default Colours'!E17=TRUE,TRUE, FALSE) -> TRUE | D15: =IF('Default Colours'!G17=TRUE,TRUE, FALSE) -> TRUE | E15: =IF('Default Colours'!I17=TRUE,TRUE, FALSE) -> FALSE | F15: =IF('Default Colours'!K17=TRUE,TRUE, FALSE) -> FALSE | G15: =IF('Default Colours'!M17=TRUE,TRUE, FALSE) -> FALSE | H15: =IF('Default Colours'!O17=TRUE,TRUE, FALSE) -> TRUE | I15: =IF('Default Colours'!Q17=TRUE,TRUE, FALSE) -> TRUE | J15: =IF('Default Colours'!S17=TRUE,TRUE, FALSE) -> TRUE | K15: =IF('Default Colours'!U17=TRUE,TRUE, FALSE) -> FALSE | L15: FALSE | M15: FALSE | N15: FALSE | O15: FALSE | P15: FALSE | Q15: FALSE | R15: FALSE | S15: FALSE | T15: FALSE | U15: FALSE | V15: FALSE | W15: FALSE | X15: FALSE | Y15: FALSE | Z15: FALSE
... A32: Pink | B32: =IF('Default Colours'!C34=TRUE,TRUE, FALSE) -> FALSE | C32: =IF('Default Colours'!E34=TRUE,TRUE, FALSE) -> TRUE | D32: =IF('Default Colours'!G34=TRUE,TRUE, FALSE) -> TRUE | E32: =IF('Default Colours'!I34=TRUE,TRUE, FALSE) -> FALSE | F32: =IF('Default Colours'!K34=TRUE,TRUE, FALSE) -> FALSE | G32: =IF('Default Colours'!M34=TRUE,TRUE, FALSE) -> TRUE | H32: =IF('Default Colours'!O34=TRUE,TRUE, FALSE) -> FALSE | I32: =IF('Default Colours'!Q34=TRUE,TRUE, FALSE) -> FALSE | J32: =IF('Default Colours'!S34=TRUE,TRUE, FALSE) -> FALSE | K32: =IF('Default Colours'!U34=TRUE,TRUE, FALSE) -> TRUE | L32: FALSE | M32: FALSE | N32: FALSE | O32: FALSE | P32: FALSE | Q32: FALSE | R32: FALSE | S32: FALSE | T32: FALSE | U32: FALSE | V32: FALSE | W32: FALSE | X32: FALSE | Y32: FALSE | Z32: FALSE
A33: Have: | B33: =COUNTIF(B4:B32, TRUE) -> 4 | C33: =COUNTIF(C4:C32, TRUE) -> 17 | D33: =COUNTIF(D4:D32, TRUE) -> 24 | E33: =COUNTIF(E4:E32, TRUE) -> 8 | F33: =COUNTIF(F4:F32, TRUE) -> 15 | G33: =COUNTIF(G4:G32, TRUE) -> 10 | H33: =COUNTIF(H4:H32, TRUE) -> 12 | I33: =COUNTIF(I4:I32, TRUE) -> 21 | ... R33: =COUNTIF(R4:R32, TRUE) -> 0 | S33: =COUNTIF(S6:S32, TRUE) -> 0 | T33: =COUNTIF(T6:T32, TRUE) -> 0 | U33: =COUNTIF(U4:U32, TRUE) -> 0 | V33: =COUNTIF(V4:V32, TRUE) -> 0 | W33: =COUNTIF(W4:W32, TRUE) -> 0 | X33: =COUNTIF(X4:X32, TRUE) -> 0 | Y33: =COUNTIF(Y4:Y32, TRUE) -> 0 | Z33: =COUNTIF(Y4:Y32, TRUE) -> 0
A34: Need: | B34: =COUNTIF(B4:B32, FALSE) -> 25 | C34: =COUNTIF(C4:C32, FALSE) -> 12 | D34: =COUNTIF(D4:D32, FALSE) -> 5 | E34: =COUNTIF(E4:E32, FALSE) -> 21 | F34: =COUNTIF(F4:F32, FALSE) -> 14 | G34: =COUNTIF(G4:G32, FALSE) -> 19 | H34: =COUNTIF(H4:H32, FALSE) -> 17 | I34: =COUNTIF(I4:I32, FALSE) -> 8 | ... R34: =COUNTIF(R4:R32, FALSE) -> 29 | S34: =COUNTIF(S6:S32, FALSE) -> 27 | T34: =COUNTIF(T6:T32, FALSE) -> 27 | U34: =COUNTIF(U4:U32, FALSE) -> 29 | V34: =COUNTIF(V4:V32, FALSE) -> 29 | W34: =COUNTIF(W4:W32, FALSE) -> 29 | X34: =COUNTIF(X4:X32, FALSE) -> 29 | Y34: =COUNTIF(Y4:Y32, FALSE) -> 29 | Z34: =COUNTIF(Y4:Y32, FALSE) -> 29

Sheet Molten
A1: Flower
B2: Blazebulb | C2: Anemone | D2: Bellbutton | E2: Dandelily | F2: Dreampuff | G2: Ghostgleam | H2: Heavy Nettle | I2: Hibiscus | J2: Penste mum | K2: Thistle | L2: Tulias | M2: Crystalia | N2: Frostfeather | O2: Bowblossom | P2: Eggwort | Q2: Glowbal | R2: Happadil | S2: Happadil | U2: Marigold | V2: Petunia | W2: Pinwheel | X2: Poinsettia | Y2: Rose | Z2: Wheat flower
A3: Pattern → Colour ↓
A4: Black | B4: =IF('Default Colours'!W6=TRUE,TRUE, FALSE) -> FALSE | C4: FALSE | D4: FALSE | E4: FALSE | F4: FALSE | G4: FALSE | H4: FALSE | I4: FALSE | J4: FALSE | K4: FALSE | L4: FALSE | M4: FALSE | N4: FALSE | O4: FALSE | P4: FALSE | Q4: FALSE | R4: FALSE | S4: FALSE | T4: FALSE | U4: FALSE | V4: FALSE | W4: FALSE | X4: FALSE | Y4: FALSE | Z4: FALSE
A5: Grey | B5: =IF('Default Colours'!W7=TRUE,TRUE, FALSE) -> FALSE | C5: FALSE | D5: FALSE | E5: FALSE | F5: FALSE | G5: FALSE | H5: FALSE | I5: FALSE | J5: FALSE | K5: FALSE | L5: FALSE | M5: FALSE | N5: FALSE | O5: FALSE | P5: FALSE | Q5: FALSE | R5: FALSE | S5: FALSE | T5: FALSE | U5: FALSE | V5: FALSE | W5: FALSE | X5: FALSE | Y5: FALSE | Z5: FALSE
A6: White | B6: =IF('Default Colours'!W8=TRUE,TRUE, FALSE) -> FALSE | C6: FALSE | D6: FALSE | E6: FALSE | F6: FALSE | G6: FALSE | H6: FALSE | I6: FALSE | J6: FALSE | K6: FALSE | L6: FALSE | M6: FALSE | N6: FALSE | O6: FALSE | P6: FALSE | Q6: FALSE | R6: FALSE | S6: FALSE | T6: FALSE | U6: FALSE | V6: FALSE | W6: FALSE | X6: FALSE | Y6: FALSE | Z6: FALSE
A7: Red | B7: =IF('Default Colours'!W9=TRUE,TRUE, FALSE) -> FALSE | C7: FALSE | D7: FALSE | E7: FALSE | F7: FALSE | G7: FALSE | H7: FALSE | I7: FALSE | J7: FALSE | K7: FALSE | L7: FALSE | M7: FALSE | N7: FALSE | O7: FALSE | P7: FALSE | Q7: FALSE | R7: FALSE | S7: FALSE | T7: FALSE | U7: FALSE | V7: FALSE | W7: FALSE | X7: FALSE | Y7: FALSE | Z7: FALSE
A8: Warm Pink | B8: =IF('Default Colours'!W10=TRUE,TRUE, FALSE) -> FALSE | C8: FALSE | D8: FALSE | E8: FALSE | F8: FALSE | G8: FALSE | H8: FALSE | I8: FALSE | J8: FALSE | K8: FALSE | L8: FALSE | M8: FALSE | N8: FALSE | O8: FALSE | P8: FALSE | Q8: FALSE | R8: FALSE | S8: FALSE | T8: FALSE | U8: FALSE | V8: FALSE | W8: FALSE | X8: FALSE | Y8: FALSE | Z8: FALSE
A9: Coral | B9: =IF('Default Colours'!W11=TRUE,TRUE, FALSE) -> FALSE | C9: FALSE | D9: FALSE | E9: FALSE | F9: FALSE | G9: FALSE | H9: FALSE | I9: FALSE | J9: FALSE | K9: FALSE | L9: FALSE | M9: FALSE | N9: FALSE | O9: FALSE | P9: FALSE | Q9: FALSE | R9: FALSE | S9: FALSE | T9: FALSE | U9: FALSE | V9: FALSE | W9: FALSE | X9: FALSE | Y9: FALSE | Z9: FALSE
A10: Blush | B10: =IF('Default Colours'!W12=TRUE,TRUE, FALSE) -> TRUE | C10: FALSE | D10: FALSE | E10: FALSE | F10: FALSE | G10: FALSE | H10: FALSE | I10: FALSE | J10: FALSE | K10: FALSE | L10: FALSE | M10: FALSE | N10: FALSE | O10: FALSE | P10: FALSE | Q10: FALSE | R10: FALSE | S10: FALSE | T10: FALSE | U10: FALSE | V10: FALSE | W10: FALSE | X10: FALSE | Y10: FALSE | Z10: FALSE
A11: Orange | B11: =IF('Default Colours'!W13=TRUE,TRUE, FALSE) -> FALSE | C11: FALSE | D11: FALSE | E11: FALSE | F11: FALSE | G11: FALSE | H11: FALSE | I11: FALSE | J11: FALSE | K11: FALSE | L11: FALSE | M11: FALSE | N11: FALSE | O11: FALSE | P11: FALSE | Q11: FALSE | R11: FALSE | S11: FALSE | T11: FALSE | U11: FALSE | V11: FALSE | W11: FALSE | X11: FALSE | Y11: FALSE | Z11: FALSE
A12: Peach | B12: =IF('Default Colours'!W14=TRUE,TRUE, FALSE) -> FALSE | C12: FALSE | D12: FALSE | E12: FALSE | F12: FALSE | G12: FALSE | H12: FALSE | I12: FALSE | J12: FALSE | K12: FALSE | L12: FALSE | M12: FALSE | N12: FALSE | O12: FALSE | P12: FALSE | Q12: FALSE | R12: FALSE | S12: FALSE | T12: FALSE | U12: FALSE | V12: FALSE | W12: FALSE | X12: FALSE | Y12: FALSE | Z12: FALSE
A13: Yellow | B13: =IF('Default Colours'!W15=TRUE,TRUE, FALSE) -> FALSE | C13: FALSE | D13: FALSE | E13: FALSE | F13: FALSE | G13: FALSE | H13: FALSE | I13: FALSE | J13: FALSE | K13: FALSE | L13: FALSE | M13: FALSE | N13: FALSE | O13: FALSE | P13: FALSE | Q13: FALSE | R13: FALSE | S13: FALSE | T13: FALSE | U13: FALSE | V13: FALSE | W13: FALSE | X13: FALSE | Y13: FALSE | Z13: FALSE
A14: Cream | B14: =IF('Default Colours'!W16=TRUE,TRUE, FALSE) -> TRUE | C14: FALSE | D14: FALSE | E14: FALSE | F14: FALSE | G14: FALSE | H14: FALSE | I14: FALSE | J14: FALSE | K14: FALSE | L14: FALSE | M14: FALSE | N14: FALSE | O14: FALSE | P14: FALSE | Q14: FALSE | R14: FALSE | S14: FALSE | T14: FALSE | U14: FALSE | V14: FALSE | W14: FALSE | X14: FALSE | Y14: FALSE | Z14: FALSE
A15: Lime | B15: =IF('Default Colours'!W17=TRUE,TRUE, FALSE) -> FALSE | C15: FALSE | D15: FALSE | E15: FALSE | F15: FALSE | G15: FALSE | H15: FALSE | I15: FALSE | J15: FALSE | K15: FALSE | L15: FALSE | M15: FALSE | N15: FALSE | O15: FALSE | P15: FALSE | Q15: FALSE | R15: FALSE | S15: FALSE | T15: FALSE | U15: FALSE | V15: FALSE | W15: FALSE | X15: FALSE | Y15: FALSE | Z15: FALSE
... A32: Pink | B32: =IF('Default Colours'!W34=TRUE,TRUE, FALSE) -> FALSE | C32: FALSE | D32: FALSE | E32: FALSE | F32: FALSE | G32: FALSE | H32: FALSE | I32: FALSE | J32: FALSE | K32: FALSE | L32: FALSE | M32: FALSE | N32: FALSE | O32: FALSE | P32: FALSE | Q32: FALSE | R32: FALSE | S32: FALSE | T32: FALSE | U32: FALSE | V32: FALSE | W32: FALSE | X32: FALSE | Y32: FALSE | Z32: FALSE
A33: Have: | B33: =COUNTIF(B4:B32, TRUE) -> 2 | C33: =COUNTIF(C4:C32, TRUE) -> 0 | D33: =COUNTIF(D4:D32, TRUE) -> 0 | E33: =COUNTIF(E4:E32, TRUE) -> 0 | F33: =COUNTIF(F4:F32, TRUE) -> 0 | G33: =COUNTIF(G4:G32, TRUE) -> 0 | H33: =COUNTIF(H4:H32, TRUE) -> 0 | I33: =COUNTIF(I4:I32, TRUE) -> 0 | ... R33: =COUNTIF(R4:R32, TRUE) -> 0 | S33: =COUNTIF(S6:S32, TRUE) -> 0 | T33: =COUNTIF(T6:T32, TRUE) -> 0 | U33: =COUNTIF(U4:U32, TRUE) -> 0 | V33: =COUNTIF(V4:V32, TRUE) -> 0 | W33: =COUNTIF(W4:W32, TRUE) -> 0 | X33: =COUNTIF(X4:X32, TRUE) -> 0 | Y33: =COUNTIF(Y4:Y32, TRUE) -> 0 | Z33: =COUNTIF(Z4:Z32, TRUE) -> 0
A34: Need: | B34: =COUNTIF(B4:B32, FALSE) -> 27 | C34: =COUNTIF(C4:C32, FALSE) -> 29 | D34: =COUNTIF(D4:D32, FALSE) -> 29 | E34: =COUNTIF(E4:E32, FALSE) -> 29 | F34: =COUNTIF(F4:F32, FALSE) -> 29 | G34: =COUNTIF(G4:G32, FALSE) -> 29 | H34: =COUNTIF(H4:H32, FALSE) -> 29 | I34: =COUNTIF(I4:I32, FALSE) -> 29 | ... R34: =COUNTIF(R4:R32, FALSE) -> 29 | S34: =COUNTIF(S6:S32, FALSE) -> 27 | T34: =COUNTIF(T6:T32, FALSE) -> 27 | U34: =COUNTIF(U4:U32, FALSE) -> 29 | V34: =COUNTIF(V4:V32, FALSE) -> 29 | W34: =COUNTIF(W4:W32, FALSE) -> 29 | X34: =COUNTIF(X4:X32, FALSE) -> 29 | Y34: =COUNTIF(Y4:Y32, FALSE) -> 29 | Z34: =COUNTIF(Z4:Z32, FALSE) -> 29

Sheet Crystal
A1: Flower
B2: Crystalia | C2: Anemone | D2: Bellbutton | E2: Dandelily | F2: Dreampuff | G2: Ghostgleam | H2: Heavy Nettle | I2: Hibiscus | J2: Penste mum | K2: Thistle | L2: Tulias | M2: Blazebulb | N2: Frostfeather | O2: Bowblossom | P2: Eggwort | Q2: Glowbal | R2: Happadil | S2: Happadil | U2: Marigold | V2: Petunia | W2: Pinwheel | X2: Poinsettia | Y2: Rose | Z2: Wheat flower
A3: Pattern → Colour ↓
A4: Black | B4: =IF('Default Colours'!Y6=TRUE,TRUE, FALSE) -> FALSE | C4: FALSE | D4: FALSE | E4: FALSE | F4: FALSE | G4: FALSE | H4: FALSE | I4: FALSE | J4: FALSE | K4: FALSE | L4: FALSE | M4: FALSE | N4: FALSE | O4: FALSE | P4: FALSE | Q4: FALSE | R4: FALSE | S4: FALSE | T4: FALSE | U4: FALSE | V4: FALSE | W4: FALSE | X4: FALSE | Y4: FALSE | Z4: FALSE
A5: Grey | B5: =IF('Default Colours'!Y7=TRUE,TRUE, FALSE) -> FALSE | C5: FALSE | D5: FALSE | E5: FALSE | F5: FALSE | G5: FALSE | H5: FALSE | I5: FALSE | J5: FALSE | K5: FALSE | L5: FALSE | M5: FALSE | N5: FALSE | O5: FALSE | P5: FALSE | Q5: FALSE | R5: FALSE | S5: FALSE | T5: FALSE | U5: FALSE | V5: FALSE | W5: FALSE | X5: FALSE | Y5: FALSE | Z5: FALSE
A6: White | B6: =IF('Default Colours'!Y8=TRUE,TRUE, FALSE) -> FALSE | C6: FALSE | D6: FALSE | E6: FALSE | F6: FALSE | G6: FALSE | H6: FALSE | I6: FALSE | J6: FALSE | K6: FALSE | L6: FALSE | M6: FALSE | N6: FALSE | O6: FALSE | P6: FALSE | Q6: FALSE | R6: FALSE | S6: FALSE | T6: FALSE | U6: FALSE | V6: FALSE | W6: FALSE | X6: FALSE | Y6: FALSE | Z6: FALSE
A7: Red | B7: =IF('Default Colours'!Y9=TRUE,TRUE, FALSE) -> FALSE | C7: FALSE | D7: FALSE | E7: FALSE | F7: FALSE | G7: FALSE | H7: FALSE | I7: FALSE | J7: FALSE | K7: FALSE | L7: FALSE | M7: FALSE | N7: FALSE | O7: FALSE | P7: FALSE | Q7: FALSE | R7: FALSE | S7: FALSE | T7: FALSE | U7: FALSE | V7: FALSE | W7: FALSE | X7: FALSE | Y7: FALSE | Z7: FALSE
A8: Warm Pink | B8: =IF('Default Colours'!Y10=TRUE,TRUE, FALSE) -> FALSE | C8: FALSE | D8: FALSE | E8: FALSE | F8: FALSE | G8: FALSE | H8: FALSE | I8: FALSE | J8: FALSE | K8: FALSE | L8: FALSE | M8: FALSE | N8: FALSE | O8: FALSE | P8: FALSE | Q8: FALSE | R8: FALSE | S8: FALSE | T8: FALSE | U8: FALSE | V8: FALSE | W8: FALSE | X8: FALSE | Y8: FALSE | Z8: FALSE
A9: Coral | B9: =IF('Default Colours'!Y11=TRUE,TRUE, FALSE) -> FALSE | C9: FALSE | D9: FALSE | E9: FALSE | F9: FALSE | G9: FALSE | H9: FALSE | I9: FALSE | J9: FALSE | K9: FALSE | L9: FALSE | M9: FALSE | N9: FALSE | O9: FALSE | P9: FALSE | Q9: FALSE | R9: FALSE | S9: FALSE | T9: FALSE | U9: FALSE | V9: FALSE | W9: FALSE | X9: FALSE | Y9: FALSE | Z9: FALSE
A10: Blush | B10: =IF('Default Colours'!Y12=TRUE,TRUE, FALSE) -> TRUE | C10: FALSE | D10: FALSE | E10: FALSE | F10: FALSE | G10: FALSE | H10: FALSE | I10: FALSE | J10: FALSE | K10: FALSE | L10: FALSE | M10: FALSE | N10: FALSE | O10: FALSE | P10: FALSE | Q10: FALSE | R10: FALSE | S10: FALSE | T10: FALSE | U10: FALSE | V10: FALSE | W10: FALSE | X10: FALSE | Y10: FALSE | Z10: FALSE
A11: Orange | B11: =IF('Default Colours'!Y13=TRUE,TRUE, FALSE) -> FALSE | C11: FALSE | D11: FALSE | E11: FALSE | F11: FALSE | G11: FALSE | H11: FALSE | I11: FALSE | J11: FALSE | K11: FALSE | L11: FALSE | M11: FALSE | N11: FALSE | O11: FALSE | P11: FALSE | Q11: FALSE | R11: FALSE | S11: FALSE | T11: FALSE | U11: FALSE | V11: FALSE | W11: FALSE | X11: FALSE | Y11: FALSE | Z11: FALSE
A12: Peach | B12: =IF('Default Colours'!Y14=TRUE,TRUE, FALSE) -> FALSE | C12: FALSE | D12: FALSE | E12: FALSE | F12: FALSE | G12: FALSE | H12: FALSE | I12: FALSE | J12: FALSE | K12: FALSE | L12: FALSE | M12: FALSE | N12: FALSE | O12: FALSE | P12: FALSE | Q12: FALSE | R12: FALSE | S12: FALSE | T12: FALSE | U12: FALSE | V12: FALSE | W12: FALSE | X12: FALSE | Y12: FALSE | Z12: FALSE
A13: Yellow | B13: =IF('Default Colours'!Y15=TRUE,TRUE, FALSE) -> FALSE | C13: FALSE | D13: FALSE | E13: FALSE | F13: FALSE | G13: FALSE | H13: FALSE | I13: FALSE | J13: FALSE | K13: FALSE | L13: FALSE | M13: FALSE | N13: FALSE | O13: FALSE | P13: FALSE | Q13: FALSE | R13: FALSE | S13: FALSE | T13: FALSE | U13: FALSE | V13: FALSE | W13: FALSE | X13: FALSE | Y13: FALSE | Z13: FALSE
A14: Cream | B14: =IF('Default Colours'!Y16=TRUE,TRUE, FALSE) -> FALSE | C14: FALSE | D14: FALSE | E14: FALSE | F14: FALSE | G14: FALSE | H14: FALSE | I14: FALSE | J14: FALSE | K14: FALSE | L14: FALSE | M14: FALSE | N14: FALSE | O14: FALSE | P14: FALSE | Q14: FALSE | R14: FALSE | S14: FALSE | T14: FALSE | U14: FALSE | V14: FALSE | W14: FALSE | X14: FALSE | Y14: FALSE | Z14: FALSE
A15: Lime | B15: =IF('Default Colours'!Y17=TRUE,TRUE, FALSE) -> FALSE | C15: FALSE | D15: FALSE | E15: FALSE | F15: FALSE | G15: FALSE | H15: FALSE | I15: FALSE | J15: FALSE | K15: FALSE | L15: FALSE | M15: FALSE | N15: FALSE | O15: FALSE | P15: FALSE | Q15: FALSE | R15: FALSE | S15: FALSE | T15: FALSE | U15: FALSE | V15: FALSE | W15: FALSE | X15: FALSE | Y15: FALSE | Z15: FALSE
... A32: Pink | B32: =IF('Default Colours'!Y34=TRUE,TRUE, FALSE) -> FALSE | C32: FALSE | D32: FALSE | E32: FALSE | F32: FALSE | G32: FALSE | H32: FALSE | I32: FALSE | J32: FALSE | K32: FALSE | L32: FALSE | M32: FALSE | N32: FALSE | O32: FALSE | P32: FALSE | Q32: FALSE | R32: FALSE | S32: FALSE | T32: FALSE | U32: FALSE | V32: FALSE | W32: FALSE | X32: FALSE | Y32: FALSE | Z32: FALSE
A33: Have: | B33: =COUNTIF(B4:B32, TRUE) -> 2 | C33: =COUNTIF(C4:C32, TRUE) -> 0 | D33: =COUNTIF(D4:D32, TRUE) -> 0 | E33: =COUNTIF(E4:E32, TRUE) -> 0 | F33: =COUNTIF(F4:F32, TRUE) -> 0 | G33: =COUNTIF(G4:G32, TRUE) -> 0 | H33: =COUNTIF(H4:H32, TRUE) -> 0 | I33: =COUNTIF(I4:I32, TRUE) -> 0 | ... R33: =COUNTIF(R4:R32, TRUE) -> 0 | S33: =COUNTIF(S6:S32, TRUE) -> 0 | T33: =COUNTIF(T6:T32, TRUE) -> 0 | U33: =COUNTIF(U4:U32, TRUE) -> 0 | V33: =COUNTIF(V4:V32, TRUE) -> 0 | W33: =COUNTIF(W4:W32, TRUE) -> 0 | X33: =COUNTIF(X4:X32, TRUE) -> 0 | Y33: =COUNTIF(Y4:Y32, TRUE) -> 0 | Z33: =COUNTIF(Y4:Y32, TRUE) -> 0
A34: Need: | B34: =COUNTIF(B4:B32, FALSE) -> 27 | C34: =COUNTIF(C4:C32, FALSE) -> 29 | D34: =COUNTIF(D4:D32, FALSE) -> 29 | E34: =COUNTIF(E4:E32, FALSE) -> 29 | F34: =COUNTIF(F4:F32, FALSE) -> 29 | G34: =COUNTIF(G4:G32, FALSE) -> 29 | H34: =COUNTIF(H4:H32, FALSE) -> 29 | I34: =COUNTIF(I4:I32, FALSE) -> 29 | ... R34: =COUNTIF(R4:R32, FALSE) -> 29 | S34: =COUNTIF(S6:S32, FALSE) -> 27 | T34: =COUNTIF(T6:T32, FALSE) -> 27 | U34: =COUNTIF(U4:U32, FALSE) -> 29 | V34: =COUNTIF(V4:V32, FALSE) -> 29 | W34: =COUNTIF(W4:W32, FALSE) -> 29 | X34: =COUNTIF(X4:X32, FALSE) -> 29 | Y34: =COUNTIF(Y4:Y32, FALSE) -> 29 | Z34: =COUNTIF(Z4:Z32, FALSE) -> 29

Sheet Frost
A1: Flower
B2: Frostfeather | C2: Anemone | D2: Bellbutton | E2: Dandelily | F2: Dreampuff | G2: Ghostgleam | H2: Heavy Nettle | I2: Hibiscus | J2: Penste mum | K2: Thistle | L2: Tulias | M2: Blazebulb | N2: Crystalia | O2: Bowblossom | P2: Eggwort | Q2: Glowbal | R2: Happadil | S2: Happadil | U2: Marigold | V2: Pinwheel | W2: Petunia | X2: Poinsettia | Y2: Rose | Z2: Wheat flower
A3: Pattern → Colour ↓
A4: Black | B4: =IF('Default Colours'!AA6=TRUE,TRUE, FALSE) -> FALSE | C4: FALSE | D4: FALSE | E4: FALSE | F4: FALSE | G4: FALSE | H4: FALSE | I4: FALSE | J4: FALSE | K4: FALSE | L4: FALSE | M4: FALSE | N4: FALSE | O4: FALSE | P4: FALSE | Q4: FALSE | R4: FALSE | S4: FALSE | T4: FALSE | U4: FALSE | V4: FALSE | W4: FALSE | X4: FALSE | Y4: FALSE | Z4: FALSE
A5: Grey | B5: =IF('Default Colours'!AA7=TRUE,TRUE, FALSE) -> FALSE | C5: FALSE | D5: FALSE | E5: FALSE | F5: FALSE | G5: FALSE | H5: FALSE | I5: FALSE | J5: FALSE | K5: FALSE | L5: FALSE | M5: FALSE | N5: FALSE | O5: FALSE | P5: FALSE | Q5: FALSE | R5: FALSE | S5: FALSE | T5: FALSE | U5: FALSE | V5: FALSE | W5: FALSE | X5: FALSE | Y5: FALSE | Z5: FALSE
A6: White | B6: =IF('Default Colours'!AA8=TRUE,TRUE, FALSE) -> FALSE | C6: FALSE | D6: FALSE | E6: FALSE | F6: FALSE | G6: FALSE | H6: FALSE | I6: FALSE | J6: FALSE | K6: FALSE | L6: FALSE | M6: FALSE | N6: FALSE | O6: FALSE | P6: FALSE | Q6: FALSE | R6: FALSE | S6: FALSE | T6: FALSE | U6: FALSE | V6: FALSE | W6: FALSE | X6: FALSE | Y6: FALSE | Z6: FALSE
A7: Red | B7: =IF('Default Colours'!AA9=TRUE,TRUE, FALSE) -> FALSE | C7: FALSE | D7: FALSE | E7: FALSE | F7: FALSE | G7: FALSE | H7: FALSE | I7: FALSE | J7: FALSE | K7: FALSE | L7: FALSE | M7: FALSE | N7: FALSE | O7: FALSE | P7: FALSE | Q7: FALSE | R7: FALSE | S7: FALSE | T7: FALSE | U7: FALSE | V7: FALSE | W7: FALSE | X7: FALSE | Y7: FALSE | Z7: FALSE
A8: Warm Pink | B8: =IF('Default Colours'!AA10=TRUE,TRUE, FALSE) -> FALSE | C8: FALSE | D8: FALSE | E8: FALSE | F8: FALSE | G8: FALSE | H8: FALSE | I8: FALSE | J8: FALSE | K8: FALSE | L8: FALSE | M8: FALSE | N8: FALSE | O8: FALSE | P8: FALSE | Q8: FALSE | R8: FALSE | S8: FALSE | T8: FALSE | U8: FALSE | V8: FALSE | W8: FALSE | X8: FALSE | Y8: FALSE | Z8: FALSE
A9: Coral | B9: =IF('Default Colours'!AA11=TRUE,TRUE, FALSE) -> FALSE | C9: FALSE | D9: FALSE | E9: FALSE | F9: FALSE | G9: FALSE | H9: FALSE | I9: FALSE | J9: FALSE | K9: FALSE | L9: FALSE | M9: FALSE | N9: FALSE | O9: FALSE | P9: FALSE | Q9: FALSE | R9: FALSE | S9: FALSE | T9: FALSE | U9: FALSE | V9: FALSE | W9: FALSE | X9: FALSE | Y9: FALSE | Z9: FALSE
A10: Blush | B10: =IF('Default Colours'!AA12=TRUE,TRUE, FALSE) -> FALSE | C10: FALSE | D10: FALSE | E10: FALSE | F10: FALSE | G10: FALSE | H10: FALSE | I10: FALSE | J10: FALSE | K10: FALSE | L10: FALSE | M10: FALSE | N10: FALSE | O10: FALSE | P10: FALSE | Q10: FALSE | R10: FALSE | S10: FALSE | T10: FALSE | U10: FALSE | V10: FALSE | W10: FALSE | X10: FALSE | Y10: FALSE | Z10: FALSE
A11: Orange | B11: =IF('Default Colours'!AA13=TRUE,TRUE, FALSE) -> FALSE | C11: FALSE | D11: FALSE | E11: FALSE | F11: FALSE | G11: FALSE | H11: FALSE | I11: FALSE | J11: FALSE | K11: FALSE | L11: FALSE | M11: FALSE | N11: FALSE | O11: FALSE | P11: FALSE | Q11: FALSE | R11: FALSE | S11: FALSE | T11: FALSE | U11: FALSE | V11: FALSE | W11: FALSE | X11: FALSE | Y11: FALSE | Z11: FALSE
A12: Peach | B12: =IF('Default Colours'!AA14=TRUE,TRUE, FALSE) -> FALSE | C12: FALSE | D12: FALSE | E12: FALSE | F12: FALSE | G12: FALSE | H12: FALSE | I12: FALSE | J12: FALSE | K12: FALSE | L12: FALSE | M12: FALSE | N12: FALSE | O12: FALSE | P12: FALSE | Q12: FALSE | R12: FALSE | S12: FALSE | T12: FALSE | U12: FALSE | V12: FALSE | W12: FALSE | X12: FALSE | Y12: FALSE | Z12: FALSE
A13: Yellow | B13: =IF('Default Colours'!AA15=TRUE,TRUE, FALSE) -> FALSE | C13: FALSE | D13: FALSE | E13: FALSE | F13: FALSE | G13: FALSE | H13: FALSE | I13: FALSE | J13: FALSE | K13: FALSE | L13: FALSE | M13: FALSE | N13: FALSE | O13: FALSE | P13: FALSE | Q13: FALSE | R13: FALSE | S13: FALSE | T13: FALSE | U13: FALSE | V13: FALSE | W13: FALSE | X13: FALSE | Y13: FALSE | Z13: FALSE
A14: Cream | B14: =IF('Default Colours'!AA16=TRUE,TRUE, FALSE) -> FALSE | C14: FALSE | D14: FALSE | E14: FALSE | F14: FALSE | G14: FALSE | H14: FALSE | I14: FALSE | J14: FALSE | K14: FALSE | L14: FALSE | M14: FALSE | N14: FALSE | O14: FALSE | P14: FALSE | Q14: FALSE | R14: FALSE | S14: FALSE | T14: FALSE | U14: FALSE | V14: FALSE | W14: FALSE | X14: FALSE | Y14: FALSE | Z14: FALSE
A15: Lime | B15: =IF('Default Colours'!AA17=TRUE,TRUE, FALSE) -> FALSE | C15: FALSE | D15: FALSE | E15: FALSE | F15: FALSE | G15: FALSE | H15: FALSE | I15: FALSE | J15: FALSE | K15: FALSE | L15: FALSE | M15: FALSE | N15: FALSE | O15: FALSE | P15: FALSE | Q15: FALSE | R15: FALSE | S15: FALSE | T15: FALSE | U15: FALSE | V15: FALSE | W15: FALSE | X15: FALSE | Y15: FALSE | Z15: FALSE
... A32: Pink | B32: =IF('Default Colours'!AA34=TRUE,TRUE, FALSE) -> FALSE | C32: FALSE | D32: FALSE | E32: FALSE | F32: FALSE | G32: FALSE | H32: FALSE | I32: FALSE | J32: FALSE | K32: FALSE | L32: FALSE | M32: FALSE | N32: FALSE | O32: FALSE | P32: FALSE | Q32: FALSE | R32: FALSE | S32: FALSE | T32: FALSE | U32: FALSE | V32: FALSE | W32: FALSE | X32: FALSE | Y32: FALSE | Z32: FALSE
A33: Have: | B33: =COUNTIF(B4:B32, TRUE) -> 1 | C33: =COUNTIF(C4:C32, TRUE) -> 0 | D33: =COUNTIF(D4:D32, TRUE) -> 0 | E33: =COUNTIF(E4:E32, TRUE) -> 0 | F33: =COUNTIF(F4:F32, TRUE) -> 0 | G33: =COUNTIF(G4:G32, TRUE) -> 0 | H33: =COUNTIF(H4:H32, TRUE) -> 0 | I33: =COUNTIF(I4:I32, TRUE) -> 0 | ... R33: =COUNTIF(R4:R32, TRUE) -> 0 | S33: =COUNTIF(S6:S32, TRUE) -> 0 | T33: =COUNTIF(T6:T32, TRUE) -> 0 | U33: =COUNTIF(U4:U32, TRUE) -> 0 | V33: =COUNTIF(V4:V32, TRUE) -> 0 | W33: =COUNTIF(W4:W32, TRUE) -> 0 | X33: =COUNTIF(X4:X32, TRUE) -> 0 | Y33: =COUNTIF(Y4:Y32, TRUE) -> 0 | Z33: =COUNTIF(Z4:Z32, TRUE) -> 0
A34: Need: | B34: =COUNTIF(B4:B32, FALSE) -> 28 | C34: =COUNTIF(C4:C32, FALSE) -> 29 | D34: =COUNTIF(D4:D32, FALSE) -> 29 | E34: =COUNTIF(E4:E32, FALSE) -> 29 | F34: =COUNTIF(F4:F32, FALSE) -> 29 | G34: =COUNTIF(G4:G32, FALSE) -> 29 | H34: =COUNTIF(H4:H32, FALSE) -> 29 | I34: =COUNTIF(I4:I32, FALSE) -> 29 | ... R34: =COUNTIF(R4:R32, FALSE) -> 29 | S34: =COUNTIF(S6:S32, FALSE) -> 27 | T34: =COUNTIF(T6:T32, FALSE) -> 27 | U34: =COUNTIF(U4:U32, FALSE) -> 29 | V34: =COUNTIF(V4:V32, FALSE) -> 29 | W34: =COUNTIF(W4:W32, FALSE) -> 29 | X34: =COUNTIF(X4:X32, FALSE) -> 29 | Y34: =COUNTIF(Y4:Y32, FALSE) -> 29 | Z34: =COUNTIF(Z4:Z32, FALSE) -> 29

Sheet Iridescent
A1: Flower
B2: Bowblossom | C2: Anemone | D2: Bellbutton | E2: Dandelily | F2: Dreampuff | G2: Ghostgleam | H2: Heavy Nettle | I2: Hibiscus | J2: Penste mum | K2: Thistle | L2: Tulias | M2: Blazebulb | N2: Crystalia | O2: Frostfeather | P2: Eggwort | Q2: Glowbal | R2: Happadil | S2: Happadil | U2: Marigold | V2: Petunia | W2: Pinwheel | X2: Poinsettia | Y2: Rose | Z2: Wheat flower
A3: Pattern → Colour ↓
A4: Black | B4: =IF('Default Colours'!AC6=TRUE,TRUE, FALSE) -> TRUE | C4: FALSE | D4: FALSE | E4: FALSE | F4: FALSE | G4: FALSE | H4: FALSE | I4: FALSE | J4: FALSE | K4: FALSE | L4: FALSE | M4: FALSE | N4: FALSE | O4: FALSE | P4: FALSE | Q4: FALSE | R4: FALSE | S4: FALSE | T4: FALSE | U4: FALSE | V4: FALSE | W4: FALSE | X4: FALSE | Y4: FALSE | Z4: FALSE
A5: Grey | B5: =IF('Default Colours'!AC7=TRUE,TRUE, FALSE) -> FALSE | C5: FALSE | D5: FALSE | E5: FALSE | F5: FALSE | G5: FALSE | H5: FALSE | I5: FALSE | J5: FALSE | K5: FALSE | L5: FALSE | M5: FALSE | N5: FALSE | O5: FALSE | P5: FALSE | Q5: FALSE | R5: FALSE | S5: FALSE | T5: FALSE | U5: FALSE | V5: FALSE | W5: FALSE | X5: FALSE | Y5: FALSE | Z5: FALSE
A6: White | B6: =IF('Default Colours'!AC8=TRUE,TRUE, FALSE) -> TRUE | C6: FALSE | D6: FALSE | E6: FALSE | F6: FALSE | G6: FALSE | H6: FALSE | I6: FALSE | J6: FALSE | K6: FALSE | L6: FALSE | M6: FALSE | N6: FALSE | O6: FALSE | P6: FALSE | Q6: FALSE | R6: FALSE | S6: FALSE | T6: FALSE | U6: FALSE | V6: FALSE | W6: FALSE | X6: FALSE | Y6: FALSE | Z6: FALSE
A7: Red | B7: =IF('Default Colours'!AC9=TRUE,TRUE, FALSE) -> FALSE | C7: FALSE | D7: FALSE | E7: FALSE | F7: FALSE | G7: FALSE | H7: FALSE | I7: FALSE | J7: FALSE | K7: FALSE | L7: FALSE | M7: FALSE | N7: FALSE | O7: FALSE | P7: FALSE | Q7: FALSE | R7: FALSE | S7: FALSE | T7: FALSE | U7: FALSE | V7: FALSE | W7: FALSE | X7: FALSE | Y7: FALSE | Z7: FALSE
A8: Warm Pink | B8: =IF('Default Colours'!AC10=TRUE,TRUE, FALSE) -> FALSE | C8: FALSE | D8: FALSE | E8: FALSE | F8: FALSE | G8: FALSE | H8: FALSE | I8: FALSE | J8: FALSE | K8: FALSE | L8: FALSE | M8: FALSE | N8: FALSE | O8: FALSE | P8: FALSE | Q8: FALSE | R8: FALSE | S8: FALSE | T8: FALSE | U8: FALSE | V8: FALSE | W8: FALSE | X8: FALSE | Y8: FALSE | Z8: FALSE
A9: Coral | B9: =IF('Default Colours'!AC11=TRUE,TRUE, FALSE) -> FALSE | C9: FALSE | D9: FALSE | E9: FALSE | F9: FALSE | G9: FALSE | H9: FALSE | I9: FALSE | J9: FALSE | K9: FALSE | L9: FALSE | M9: FALSE | N9: FALSE | O9: FALSE | P9: FALSE | Q9: FALSE | R9: FALSE | S9: FALSE | T9: FALSE | U9: FALSE | V9: FALSE | W9: FALSE | X9: FALSE | Y9: FALSE | Z9: FALSE
A10: Blush | B10: =IF('Default Colours'!AC12=TRUE,TRUE, FALSE) -> FALSE | C10: FALSE | D10: FALSE | E10: FALSE | F10: FALSE | G10: FALSE | H10: FALSE | I10: FALSE | J10: FALSE | K10: FALSE | L10: FALSE | M10: FALSE | N10: FALSE | O10: FALSE | P10: FALSE | Q10: FALSE | R10: FALSE | S10: FALSE | T10: FALSE | U10: FALSE | V10: FALSE | W10: FALSE | X10: FALSE | Y10: FALSE | Z10: FALSE
A11: Orange | B11: =IF('Default Colours'!AC13=TRUE,TRUE, FALSE) -> FALSE | C11: FALSE | D11: FALSE | E11: FALSE | F11: FALSE | G11: FALSE | H11: FALSE | I11: FALSE | J11: FALSE | K11: FALSE | L11: FALSE | M11: FALSE | N11: FALSE | O11: FALSE | P11: FALSE | Q11: FALSE | R11: FALSE | S11: FALSE | T11: FALSE | U11: FALSE | V11: FALSE | W11: FALSE | X11: FALSE | Y11: FALSE | Z11: FALSE
A12: Peach | B12: =IF('Default Colours'!AC14=TRUE,TRUE, FALSE) -> FALSE | C12: FALSE | D12: FALSE | E12: FALSE | F12: FALSE | G12: FALSE | H12: FALSE | I12: FALSE | J12: FALSE | K12: FALSE | L12: FALSE | M12: FALSE | N12: FALSE | O12: FALSE | P12: FALSE | Q12: FALSE | R12: FALSE | S12: FALSE | T12: FALSE | U12: FALSE | V12: FALSE | W12: FALSE | X12: FALSE | Y12: FALSE | Z12: FALSE
A13: Yellow | B13: =IF('Default Colours'!AC15=TRUE,TRUE, FALSE) -> FALSE | C13: FALSE | D13: FALSE | E13: FALSE | F13: FALSE | G13: FALSE | H13: FALSE | I13: FALSE | J13: FALSE | K13: FALSE | L13: FALSE | M13: FALSE | N13: FALSE | O13: FALSE | P13: FALSE | Q13: FALSE | R13: FALSE | S13: FALSE | T13: FALSE | U13: FALSE | V13: FALSE | W13: FALSE | X13: FALSE | Y13: FALSE | Z13: FALSE
A14: Cream | B14: =IF('Default Colours'!AC16=TRUE,TRUE, FALSE) -> FALSE | C14: FALSE | D14: FALSE | E14: FALSE | F14: FALSE | G14: FALSE | H14: FALSE | I14: FALSE | J14: FALSE | K14: FALSE | L14: FALSE | M14: FALSE | N14: FALSE | O14: FALSE | P14: FALSE | Q14: FALSE | R14: FALSE | S14: FALSE | T14: FALSE | U14: FALSE | V14: FALSE | W14: FALSE | X14: FALSE | Y14: FALSE | Z14: FALSE
A15: Lime | B15: =IF('Default Colours'!AC17=TRUE,TRUE, FALSE) -> FALSE | C15: FALSE | D15: FALSE | E15: FALSE | F15: FALSE | G15: FALSE | H15: FALSE | I15: FALSE | J15: FALSE | K15: FALSE | L15: FALSE | M15: FALSE | N15: FALSE | O15: FALSE | P15: FALSE | Q15: FALSE | R15: FALSE | S15: FALSE | T15: FALSE | U15: FALSE | V15: FALSE | W15: FALSE | X15: FALSE | Y15: FALSE | Z15: FALSE
... A32: Pink | B32: =IF('Default Colours'!AC34=TRUE,TRUE, FALSE) -> FALSE | C32: FALSE | D32: FALSE | E32: FALSE | F32: FALSE | G32: FALSE | H32: FALSE | I32: FALSE | J32: FALSE | K32: FALSE | L32: FALSE | M32: FALSE | N32: FALSE | O32: FALSE | P32: FALSE | Q32: FALSE | R32: FALSE | S32: FALSE | T32: FALSE | U32: FALSE | V32: FALSE | W32: FALSE | X32: FALSE | Y32: FALSE | Z32: FALSE
A33: Have: | B33: =COUNTIF(B4:B32, TRUE) -> 3 | C33: =COUNTIF(C4:C32, TRUE) -> 0 | D33: =COUNTIF(D4:D32, TRUE) -> 0 | E33: =COUNTIF(E4:E32, TRUE) -> 0 | F33: =COUNTIF(F4:F32, TRUE) -> 0 | G33: =COUNTIF(G4:G32, TRUE) -> 0 | H33: =COUNTIF(H4:H32, TRUE) -> 0 | I33: =COUNTIF(I4:I32, TRUE) -> 0 | ... R33: =COUNTIF(R4:R32, TRUE) -> 0 | S33: =COUNTIF(S6:S32, TRUE) -> 0 | T33: =COUNTIF(T6:T32, TRUE) -> 0 | U33: =COUNTIF(U4:U32, TRUE) -> 0 | V33: =COUNTIF(V4:V32, TRUE) -> 0 | W33: =COUNTIF(W4:W32, TRUE) -> 0 | X33: =COUNTIF(X4:X32, TRUE) -> 0 | Y33: =COUNTIF(Y4:Y32, TRUE) -> 0 | Z33: =COUNTIF(Z4:Z32, TRUE) -> 0
A34: Need: | B34: =COUNTIF(B4:B32, FALSE) -> 26 | C34: =COUNTIF(C4:C32, FALSE) -> 29 | D34: =COUNTIF(D4:D32, FALSE) -> 29 | E34: =COUNTIF(E4:E32, FALSE) -> 29 | F34: =COUNTIF(F4:F32, FALSE) -> 29 | G34: =COUNTIF(G4:G32, FALSE) -> 29 | H34: =COUNTIF(H4:H32, FALSE) -> 29 | I34: =COUNTIF(I4:I32, FALSE) -> 29 | ... R34: =COUNTIF(R4:R32, FALSE) -> 29 | S34: =COUNTIF(S6:S32, FALSE) -> 27 | T34: =COUNTIF(T6:T32, FALSE) -> 27 | U34: =COUNTIF(U4:U32, FALSE) -> 29 | V34: =COUNTIF(V4:V32, FALSE) -> 29 | W34: =COUNTIF(W4:W32, FALSE) -> 29 | X34: =COUNTIF(X4:X32, FALSE) -> 29 | Y34: =COUNTIF(Y4:Y32, FALSE) -> 29 | Z34: =COUNTIF(Z4:Z32, FALSE) -> 29

Sheet Speckled
A1: Flower
B2: Eggwort | C2: Bellbutton | D2: Dandelily | E2: Hibiscus | F2: Penstemum | G2: Tulias | H2: Blazebulb | I2: Frostfeather | J2: Bowblossom | K2: Happadil | L2: Happadil | N2: Petunia | O2: Pinwheel | P2: Poinsettia | Q2: Rose | R2: Wheat flower
A3: Pattern → Colour ↓
A4: Black | B4: =IF('Default Colours'!AE6=TRUE,TRUE, FALSE) -> FALSE | C4: FALSE | D4: FALSE | E4: FALSE | F4: FALSE | G4: FALSE | H4: FALSE | I4: FALSE | J4: FALSE | K4: FALSE | L4: FALSE | M4: FALSE | N4: FALSE | O4: FALSE | P4: FALSE | Q4: FALSE | R4: FALSE
A5: Grey | B5: =IF('Default Colours'!AE7=TRUE,TRUE, FALSE) -> FALSE | C5: FALSE | D5: FALSE | E5: FALSE | F5: FALSE | G5: FALSE | H5: FALSE | I5: FALSE | J5: FALSE | K5: FALSE | L5: FALSE | M5: FALSE | N5: FALSE | O5: FALSE | P5: FALSE | Q5: FALSE | R5: FALSE
A6: White | B6: FALSE | C6: FALSE | D6: FALSE | E6: FALSE | F6: FALSE | G6: FALSE | H6: FALSE | I6: FALSE | J6: FALSE | K6: FALSE | L6: FALSE | M6: FALSE | N6: FALSE | O6: FALSE | P6: FALSE | Q6: FALSE | R6: FALSE
A7: Red | B7: =IF('Default Colours'!AE9=TRUE,TRUE, FALSE) -> FALSE | C7: FALSE | D7: FALSE | E7: FALSE | F7: FALSE | G7: FALSE | H7: FALSE | I7: FALSE | J7: FALSE | K7: FALSE | L7: FALSE | M7: FALSE | N7: FALSE | O7: FALSE | P7: FALSE | Q7: FALSE | R7: FALSE
A8: Warm Pink | B8: =IF('Default Colours'!AE10=TRUE,TRUE, FALSE) -> FALSE | C8: FALSE | D8: FALSE | E8: FALSE | F8: FALSE | G8: FALSE | H8: FALSE | I8: FALSE | J8: FALSE | K8: FALSE | L8: FALSE | M8: FALSE | N8: FALSE | O8: FALSE | P8: FALSE | Q8: FALSE | R8: FALSE
A9: Coral | B9: =IF('Default Colours'!AE11=TRUE,TRUE, FALSE) -> FALSE | C9: FALSE | D9: FALSE | E9: FALSE | F9: FALSE | G9: FALSE | H9: FALSE | I9: FALSE | J9: FALSE | K9: FALSE | L9: FALSE | M9: FALSE | N9: FALSE | O9: FALSE | P9: FALSE | Q9: FALSE | R9: FALSE
A10: Blush | B10: =IF('Default Colours'!AE12=TRUE,TRUE, FALSE) -> FALSE | C10: FALSE | D10: FALSE | E10: FALSE | F10: FALSE | G10: FALSE | H10: FALSE | I10: FALSE | J10: FALSE | K10: FALSE | L10: FALSE | M10: FALSE | N10: FALSE | O10: FALSE | P10: FALSE | Q10: FALSE | R10: FALSE
A11: Orange | B11: =IF('Default Colours'!AE13=TRUE,TRUE, FALSE) -> FALSE | C11: FALSE | D11: FALSE | E11: FALSE | F11: FALSE | G11: FALSE | H11: FALSE | I11: FALSE | J11: FALSE | K11: FALSE | L11: FALSE | M11: FALSE | N11: FALSE | O11: FALSE | P11: FALSE | Q11: FALSE | R11: FALSE
A12: Peach | B12: =IF('Default Colours'!AE14=TRUE,TRUE, FALSE) -> FALSE | C12: FALSE | D12: FALSE | E12: FALSE | F12: FALSE | G12: FALSE | H12: FALSE | I12: FALSE | J12: FALSE | K12: FALSE | L12: FALSE | M12: FALSE | N12: FALSE | O12: FALSE | P12: FALSE | Q12: FALSE | R12: FALSE
A13: Yellow | B13: =IF('Default Colours'!AE15=TRUE,TRUE, FALSE) -> FALSE | C13: FALSE | D13: FALSE | E13: FALSE | F13: FALSE | G13: FALSE | H13: FALSE | I13: FALSE | J13: FALSE | K13: FALSE | L13: FALSE | M13: FALSE | N13: FALSE | O13: FALSE | P13: FALSE | Q13: FALSE | R13: FALSE
A14: Cream | B14: =IF('Default Colours'!AE16=TRUE,TRUE, FALSE) -> FALSE | C14: FALSE | D14: FALSE | E14: FALSE | F14: FALSE | G14: FALSE | H14: FALSE | I14: FALSE | J14: FALSE | K14: FALSE | L14: FALSE | M14: FALSE | N14: FALSE | O14: FALSE | P14: FALSE | Q14: FALSE | R14: FALSE
A15: Lime | B15: =IF('Default Colours'!AE17=TRUE,TRUE, FALSE) -> FALSE | C15: FALSE | D15: FALSE | E15: FALSE | F15: FALSE | G15: FALSE | H15: FALSE | I15: FALSE | J15: FALSE | K15: FALSE | L15: FALSE | M15: FALSE | N15: FALSE | O15: FALSE | P15: FALSE | Q15: FALSE | R15: FALSE
A16: Pistachio | B16: =IF('Default Colours'!AE18=TRUE,TRUE, FALSE) -> FALSE | C16: FALSE | D16: FALSE | E16: FALSE | F16: FALSE | G16: FALSE | H16: FALSE | I16: FALSE | J16: FALSE | K16: FALSE | L16: FALSE | M16: FALSE | N16: FALSE | O16: FALSE | P16: FALSE | Q16: FALSE | R16: FALSE
A17: Green | B17: =IF('Default Colours'!AE19=TRUE,TRUE, FALSE) -> FALSE | C17: FALSE | D17: FALSE | E17: FALSE | F17: FALSE | G17: FALSE | H17: FALSE | I17: FALSE | J17: FALSE | K17: FALSE | L17: FALSE | M17: FALSE | N17: FALSE | O17: FALSE | P17: FALSE | Q17: FALSE | R17: FALSE
A18: Mint | B18: =IF('Default Colours'!AE20=TRUE,TRUE, FALSE) -> FALSE | C18: FALSE | D18: FALSE | E18: FALSE | F18: FALSE | G18: FALSE | H18: FALSE | I18: FALSE | J18: FALSE | K18: FALSE | L18: FALSE | M18: FALSE | N18: FALSE | O18: FALSE | P18: FALSE | Q18: FALSE | R18: FALSE
... A32: Pink | B32: =IF('Default Colours'!AE34=TRUE,TRUE, FALSE) -> FALSE | C32: FALSE | D32: FALSE | E32: FALSE | F32: FALSE | G32: FALSE | H32: FALSE | I32: FALSE | J32: FALSE | K32: FALSE | L32: FALSE | M32: FALSE | N32: FALSE | O32: FALSE | P32: FALSE | Q32: FALSE | R32: FALSE
A33: Have: | B33: =COUNTIF(B4:B32, TRUE) -> 0 | C33: =COUNTIF(C4:C32, TRUE) -> 0 | D33: =COUNTIF(D4:D32, TRUE) -> 0 | E33: =COUNTIF(E4:E32, TRUE) -> 0 | F33: =COUNTIF(F4:F32, TRUE) -> 0 | G33: =COUNTIF(G4:G32, TRUE) -> 0 | H33: =COUNTIF(H4:H32, TRUE) -> 0 | I33: =COUNTIF(I4:I32, TRUE) -> 0 | ... K33: =COUNTIF(K4:K32, TRUE) -> 0 | L33: =COUNTIF(L6:L32, TRUE) -> 0 | M33: =COUNTIF(M6:M32, TRUE) -> 0 | N33: =COUNTIF(N4:N32, TRUE) -> 0 | O33: =COUNTIF(O4:O32, TRUE) -> 0 | P33: =COUNTIF(P4:P32, TRUE) -> 0 | Q33: =COUNTIF(Q4:Q32, TRUE) -> 0 | R33: =COUNTIF(R4:R32, TRUE) -> 0
A34: Need: | B34: =COUNTIF(B4:B32, FALSE) -> 29 | C34: =COUNTIF(C4:C32, FALSE) -> 29 | D34: =COUNTIF(D4:D32, FALSE) -> 29 | E34: =COUNTIF(E4:E32, FALSE) -> 29 | F34: =COUNTIF(F4:F32, FALSE) -> 29 | G34: =COUNTIF(G4:G32, FALSE) -> 29 | H34: =COUNTIF(H4:H32, FALSE) -> 29 | I34: =COUNTIF(I4:I32, FALSE) -> 29 | ... K34: =COUNTIF(K4:K32, FALSE) -> 29 | L34: =COUNTIF(L6:L32, FALSE) -> 27 | M34: =COUNTIF(M6:M32, FALSE) -> 27 | N34: =COUNTIF(N4:N32, FALSE) -> 29 | O34: =COUNTIF(O4:O32, FALSE) -> 29 | P34: =COUNTIF(P4:P32, FALSE) -> 29 | Q34: =COUNTIF(Q4:Q32, FALSE) -> 29 | R34: =COUNTIF(R4:R32, FALSE) -> 29

Sheet Glow
A1: Flower
B2: Glowbal | C2: Anemone | D2: Bellbutton | E2: Dandelily | F2: Dreampuff | G2: Ghostgleam | H2: Heavy Nettle | I2: Hibiscus | J2: Penste mum | K2: Thistle | L2: Tulias | M2: Blazebulb | N2: Crystalia | O2: Frostfeather | P2: Bowblossom | Q2: Eggwort | R2: Happadil | S2: Happadil | U2: Marigold | V2: Petunia | W2: Pinwheel | X2: Poinsettia | Y2: Rose | Z2: Wheat flower
A3: Pattern → Colour ↓
A4: Black | B4: =IF('Default Colours'!AG6=TRUE,TRUE, FALSE) -> FALSE | C4: FALSE | D4: FALSE | E4: FALSE | F4: FALSE | G4: FALSE | H4: FALSE | I4: FALSE | J4: FALSE | K4: FALSE | L4: FALSE | M4: FALSE | N4: FALSE | O4: FALSE | P4: FALSE | Q4: FALSE | R4: FALSE | S4: FALSE | T4: FALSE | U4: FALSE | V4: FALSE | W4: FALSE | X4: FALSE | Y4: FALSE | Z4: FALSE
A5: Grey | B5: =IF('Default Colours'!AG7=TRUE,TRUE, FALSE) -> FALSE | C5: FALSE | D5: FALSE | E5: FALSE | F5: FALSE | G5: FALSE | H5: FALSE | I5: FALSE | J5: FALSE | K5: FALSE | L5: FALSE | M5: FALSE | N5: FALSE | O5: FALSE | P5: FALSE | Q5: FALSE | R5: FALSE | S5: FALSE | T5: FALSE | U5: FALSE | V5: FALSE | W5: FALSE | X5: FALSE | Y5: FALSE | Z5: FALSE
A6: White | B6: =IF('Default Colours'!AG8=TRUE,TRUE, FALSE) -> TRUE | C6: FALSE | D6: FALSE | E6: FALSE | F6: FALSE | G6: FALSE | H6: FALSE | I6: FALSE | J6: FALSE | K6: FALSE | L6: FALSE | M6: FALSE | N6: FALSE | O6: FALSE | P6: FALSE | Q6: FALSE | R6: FALSE | S6: FALSE | T6: FALSE | U6: FALSE | V6: FALSE | W6: FALSE | X6: FALSE | Y6: FALSE | Z6: FALSE
A7: Red | B7: =IF('Default Colours'!AG9=TRUE,TRUE, FALSE) -> TRUE | C7: FALSE | D7: FALSE | E7: FALSE | F7: FALSE | G7: FALSE | H7: FALSE | I7: FALSE | J7: FALSE | K7: FALSE | L7: FALSE | M7: FALSE | N7: FALSE | O7: FALSE | P7: FALSE | Q7: FALSE | R7: FALSE | S7: FALSE | T7: FALSE | U7: FALSE | V7: FALSE | W7: FALSE | X7: FALSE | Y7: FALSE | Z7: FALSE
A8: Warm Pink | B8: =IF('Default Colours'!AG10=TRUE,TRUE, FALSE) -> FALSE | C8: FALSE | D8: FALSE | E8: FALSE | F8: FALSE | G8: FALSE | H8: FALSE | I8: FALSE | J8: FALSE | K8: FALSE | L8: FALSE | M8: FALSE | N8: FALSE | O8: FALSE | P8: FALSE | Q8: FALSE | R8: FALSE | S8: FALSE | T8: FALSE | U8: FALSE | V8: FALSE | W8: FALSE | X8: FALSE | Y8: FALSE | Z8: FALSE
A9: Coral | B9: =IF('Default Colours'!AG11=TRUE,TRUE, FALSE) -> FALSE | C9: FALSE | D9: FALSE | E9: FALSE | F9: FALSE | G9: FALSE | H9: FALSE | I9: FALSE | J9: FALSE | K9: FALSE | L9: FALSE | M9: FALSE | N9: FALSE | O9: FALSE | P9: FALSE | Q9: FALSE | R9: FALSE | S9: FALSE | T9: FALSE | U9: FALSE | V9: FALSE | W9: FALSE | X9: FALSE | Y9: FALSE | Z9: FALSE
A10: Blush | B10: =IF('Default Colours'!AG12=TRUE,TRUE, FALSE) -> FALSE | C10: FALSE | D10: FALSE | E10: FALSE | F10: FALSE | G10: FALSE | H10: FALSE | I10: FALSE | J10: FALSE | K10: FALSE | L10: FALSE | M10: FALSE | N10: FALSE | O10: FALSE | P10: FALSE | Q10: FALSE | R10: FALSE | S10: FALSE | T10: FALSE | U10: FALSE | V10: FALSE | W10: FALSE | X10: FALSE | Y10: FALSE | Z10: FALSE
A11: Orange | B11: =IF('Default Colours'!AG13=TRUE,TRUE, FALSE) -> FALSE | C11: FALSE | D11: FALSE | E11: FALSE | F11: FALSE | G11: FALSE | H11: FALSE | I11: FALSE | J11: FALSE | K11: FALSE | L11: FALSE | M11: FALSE | N11: FALSE | O11: FALSE | P11: FALSE | Q11: FALSE | R11: FALSE | S11: FALSE | T11: FALSE | U11: FALSE | V11: FALSE | W11: FALSE | X11: FALSE | Y11: FALSE | Z11: FALSE
A12: Peach | B12: =IF('Default Colours'!AG14=TRUE,TRUE, FALSE) -> FALSE | C12: FALSE | D12: FALSE | E12: FALSE | F12: FALSE | G12: FALSE | H12: FALSE | I12: FALSE | J12: FALSE | K12: FALSE | L12: FALSE | M12: FALSE | N12: FALSE | O12: FALSE | P12: FALSE | Q12: FALSE | R12: FALSE | S12: FALSE | T12: FALSE | U12: FALSE | V12: FALSE | W12: FALSE | X12: FALSE | Y12: FALSE | Z12: FALSE
